<?xml version="1.0" ?>
<!-- =================================================================================== -->
<!-- |    This document was autogenerated by xacro from mit_humanoid.xacro             | -->
<!-- |    EDITING THIS FILE BY HAND IS NOT RECOMMENDED                                 | -->
<!-- =================================================================================== -->
<robot name="mit_humanoid">
  <link name="left_hip_yaw">
    <inertial>
      <origin rpy="0 0 0" xyz="-0.065362 -0.000128 -0.063947"/>
      <mass value="0.842752"/>
      <inertia ixx="0.001502" ixy="0.0" ixz="0.000533" iyy="0.001361" iyz="0.0" izz="0.001170"/>
    </inertial>
    <visual>
      <origin rpy="0 0 0" xyz="0 0 0"/>
      <geometry>
        <mesh filename="package://humanoid_description/meshes/mit_humanoid/left_hip_yaw.stl" scale="0.001 0.001 0.001"/>
      </geometry>
    </visual>
  </link>
  <joint name="left_hip_yaw_joint" type="revolute">
    <origin rpy="0 -0.174533 0" xyz="0 0.082 0"/>
    <parent link="torso"/>
    <child link="left_hip_yaw"/>
    <axis xyz="0 0 1"/>
    <limit effort="999" lower="-6.28" upper="6.28" velocity="50"/>
    <dynamics damping="0.01" friction="0.2"/>
  </joint>
  <link name="left_hip_abad">
    <inertial>
      <origin rpy="0 0 0" xyz="0.067579 -0.013035 0.000132"/>
      <mass value="1.199631"/>
      <inertia ixx="0.001745" ixy="-0.000003" ixz="0.000082" iyy="0.003338" iyz="-0.000010" izz="0.001951"/>
    </inertial>
    <visual>
      <origin rpy="0 0 0" xyz="0 0 0"/>
      <geometry>
        <mesh filename="package://humanoid_description/meshes/mit_humanoid/left_hip_abad.stl" scale="0.001 0.001 0.001"/>
      </geometry>
    </visual>
  </link>
  <joint name="left_hip_abad_joint" type="revolute">
    <origin rpy="0.0 0.436332 0.0" xyz="-0.06435 0 -0.07499"/>
    <parent link="left_hip_yaw"/>
    <child link="left_hip_abad"/>
    <axis xyz="1 0 0"/>
    <limit effort="999" lower="-6.28" upper="6.28" velocity="50"/>
    <dynamics damping="0.01" friction="0.2" rotor_inertia="0.01188"/>
  </joint>
  <link name="left_upper_leg">
    <inertial>
      <origin rpy="0 0 0" xyz="-0.001100 0.026032 -0.078842"/>
      <mass value="2.634789"/>
      <inertia ixx="0.024489" ixy="-0.000068" ixz="0.000512" iyy="0.026049" iyz="-0.002657" izz="0.003812"/>
    </inertial>
    <visual>
      <origin rpy="0 0 0" xyz="0 0 0"/>
      <geometry>
        <mesh filename="package://humanoid_description/meshes/mit_humanoid/left_leg_upper.stl" scale="0.001 0.001 0.001"/>
      </geometry>
    </visual>
    <collision>
      <origin rpy="0 0 0" xyz="0.0 0.0 -0.16"/>
      <geometry>
        <cylinder length="0.18" radius="0.035"/>
      </geometry>
    </collision>
  </link>
  <joint name="left_hip_pitch_joint" type="revolute">
    <origin rpy="0 -0.261799 0" xyz="0.08837 -0.00284 -0.01385"/>
    <parent link="left_hip_abad"/>
    <child link="left_upper_leg"/>
    <axis xyz="0 1 0"/>
    <limit effort="999" lower="-6.28" upper="6.28" velocity="50"/>
    <dynamics damping="0.01" friction="0.2" rotor_inertia="0.0198"/>
  </joint>
  <link name="left_lower_leg">
    <inertial>
      <origin rpy="0 0 0" xyz="0.005232 0.000457 -0.131581"/>
      <mass value="0.346291"/>
      <inertia ixx="0.002952" ixy="0.0" ixz="0.000083" iyy="0.002943" iyz="0.0" izz="0.000238"/>
      <mass value="0.001"/>
      <inertia ixx="0.001" ixy="0.001" ixz="0.001" iyy="0.001" iyz="0.001" izz="0.001"/>
    </inertial>
    <visual>
      <origin rpy="0 0 0" xyz="0 0 0"/>
      <geometry>
        <mesh filename="package://humanoid_description/meshes/mit_humanoid/left_leg_lower.stl" scale="0.001 0.001 0.001"/>
      </geometry>
    </visual>
    <collision>
      <origin rpy="0 0 0" xyz="0.0 0.0 -0.15"/>
      <geometry>
        <cylinder length="0.16" radius="0.035"/>
      </geometry>
    </collision>
  </link>
  <joint name="left_knee_joint" type="revolute">
    <origin rpy="0 0 0" xyz="-0.01306 0.0 -0.24916"/>
    <parent link="left_upper_leg"/>
    <child link="left_lower_leg"/>
    <axis xyz="0 1 0"/>
    <limit effort="999" lower="-6.28" upper="6.28" velocity="50"/>
    <dynamics damping="0.01" friction="0.2" rotor_inertia="0.0792"/>
  </joint>
  <link name="left_foot">
    <inertial>
      <origin rpy="0 0 0" xyz="0.022696 0.0 -0.013879"/>
      <mass value="0.279583"/>
      <inertia ixx="0.000092" ixy="0.0" ixz="-0.000054" iyy="0.08" iyz="0.0" izz="0.000769"/>
    </inertial>
    <visual>
      <origin rpy="0 0 0" xyz="0 0 0"/>
      <geometry>
        <mesh filename="package://humanoid_description/meshes/mit_humanoid/left_foot.stl" scale="0.001 0.001 0.001"/>
      </geometry>
    </visual>
    <collision>
      <origin rpy="1.57079 0 0" xyz="0.02 0.0 -0.03"/>
      <geometry>
        <box size="0.17 0.02 0.05"/>
      </geometry>
    </collision>
  </link>
  <joint name="left_ankle_joint" type="revolute">
    <origin rpy="0 0 0" xyz="0.0 0.0 -0.2785"/>
    <parent link="left_lower_leg"/>
    <child link="left_foot"/>
    <axis xyz="0 1 0"/>
    <limit effort="999" lower="-6.28" upper="6.28" velocity="50"/>
    <dynamics damping="0.01" friction="0.2" rotor_inertia="0.04752"/>
  </joint>
  <link name="right_hip_yaw">
    <inertial>
      <origin rpy="0 0 0" xyz="-0.065362 0.000128 -0.063947"/>
      <mass value="0.842752"/>
      <inertia ixx="0.001502" ixy="0.0" ixz="0.000533" iyy="0.001361" iyz="0.0" izz="0.001170"/>
    </inertial>
    <visual>
      <origin rpy="0 0 0" xyz="0 0 0"/>
      <geometry>
        <mesh filename="package://humanoid_description/meshes/mit_humanoid/left_hip_yaw.stl" scale="0.001 -0.001 0.001"/>
      </geometry>
    </visual>
  </link>
  <joint name="right_hip_yaw_joint" type="revolute">
    <origin rpy="0 -0.174533 0" xyz="0 -0.082 0"/>
    <parent link="torso"/>
    <child link="right_hip_yaw"/>
    <axis xyz="0 0 1"/>
    <limit effort="999" lower="-6.28" upper="6.28" velocity="50"/>
    <dynamics damping="0.01" friction="0.2" rotor_inertia="0.01188"/>
  </joint>
  <link name="right_hip_abad">
    <inertial>
      <origin rpy="0 0 0" xyz="0.067579 0.013035 0.000132"/>
      <mass value="1.199631"/>
      <inertia ixx="0.001745" ixy="0.000003" ixz="0.000082" iyy="0.003338" iyz="0.000010" izz="0.001951"/>
    </inertial>
    <visual>
      <origin rpy="0 0 0" xyz="0 0 0"/>
      <geometry>
        <mesh filename="package://humanoid_description/meshes/mit_humanoid/left_hip_abad.stl" scale="0.001 -0.001 0.001"/>
      </geometry>
    </visual>
  </link>
  <joint name="right_hip_abad_joint" type="revolute">
    <origin rpy="0.0 0.436332 0.0" xyz="-0.06435 0 -0.07499"/>
    <parent link="right_hip_yaw"/>
    <child link="right_hip_abad"/>
    <axis xyz="1 0 0"/>
    <limit effort="999" lower="-6.28" upper="6.28" velocity="50"/>
    <dynamics damping="0.01" friction="0.2" rotor_inertia="0.01188"/>
  </joint>
  <link name="right_upper_leg">
    <inertial>
      <origin rpy="0 0 0" xyz="-0.001100 -0.026032 -0.078842"/>
      <mass value="2.634789"/>
      <inertia ixx="0.024489" ixy="0.000068" ixz="0.000512" iyy="0.026049" iyz="0.002657" izz="0.003812"/>
    </inertial>
    <visual>
      <origin rpy="0 0 0" xyz="0 0 0"/>
      <geometry>
        <mesh filename="package://humanoid_description/meshes/mit_humanoid/left_leg_upper.stl" scale="0.001 -0.001 0.001"/>
      </geometry>
    </visual>
    <collision>
      <origin rpy="0 0 0" xyz="0.0 0.0 -0.16"/>
      <geometry>
        <cylinder length="0.18" radius="0.035"/>
      </geometry>
    </collision>
  </link>
  <joint name="right_hip_pitch_joint" type="revolute">
    <origin rpy="0 -0.261799 0" xyz="0.08837 0.00284 -0.01385"/>
    <parent link="right_hip_abad"/>
    <child link="right_upper_leg"/>
    <axis xyz="0 1 0"/>
    <limit effort="999" lower="-6.28" upper="6.28" velocity="50"/>
    <dynamics damping="0.01" friction="0.2" rotor_inertia="0.0198"/>
  </joint>
  <link name="right_lower_leg">
    <inertial>
      <origin rpy="0 0 0" xyz="0.005232 -0.000457 -0.131581"/>
      <mass value="0.346291"/>
      <inertia ixx="0.002952" ixy="0.0" ixz="0.000083" iyy="0.002943" iyz="0.0" izz="0.000238"/>
    </inertial>
    <visual>
      <origin rpy="0 0 0" xyz="0 0 0"/>
      <geometry>
        <mesh filename="package://humanoid_description/meshes/mit_humanoid/left_leg_lower.stl" scale="0.001 -0.001 0.001"/>
      </geometry>
    </visual>
    <collision>
      <origin rpy="0 0 0" xyz="0.0 0.0 -0.16"/>
      <geometry>
        <cylinder length="0.18" radius="0.035"/>
      </geometry>
    </collision>
  </link>
  <joint name="right_knee_joint" type="revolute">
    <origin rpy="0 0 0" xyz="-0.01306 0.0 -0.24916"/>
    <parent link="right_upper_leg"/>
    <child link="right_lower_leg"/>
    <axis xyz="0 1 0"/>
    <limit effort="999" lower="-6.28" upper="6.28" velocity="50"/>
    <dynamics damping="0.01" friction="0.2" rotor_inertia="0.0792"/>
  </joint>
  <link name="right_foot">
    <inertial>
      <origin rpy="0 0 0" xyz="0.022696 0.0 -0.013879"/>
      <mass value="0.279583"/>
      <inertia ixx="0.000092" ixy="0.0" ixz="-0.000054" iyy="0.08" iyz="0.0" izz="0.000769"/>
    </inertial>
    <visual>
      <origin rpy="0 0 0" xyz="0 0 0"/>
      <geometry>
        <mesh filename="package://humanoid_description/meshes/mit_humanoid/left_foot.stl" scale="0.001 -0.001 0.001"/>
      </geometry>
    </visual>
    <collision>
      <origin rpy="1.57079 0 0" xyz="0.02 0.0 -0.03"/>
      <geometry>
        <box size="0.17 0.02 0.05"/>
      </geometry>
    </collision>
  </link>
  <joint name="right_ankle_joint" type="revolute">
    <origin rpy="0 0 0" xyz="0.0 0.0 -0.2785"/>
    <parent link="right_lower_leg"/>
    <child link="right_foot"/>
    <axis xyz="0 1 0"/>
    <limit effort="999" lower="-6.28" upper="6.28" velocity="50"/>
    <dynamics damping="0.01" friction="0.2" rotor_inertia="0.04752"/>
  </joint>
  <link name="left_shoulder">
    <inertial>
      <origin rpy="0 0 0" xyz="0.009518 0.053027 0.000060"/>
      <mass value="0.788506"/>
      <inertia ixx="0.001363" ixy="0.000024" ixz="-0.000002" iyy="0.000759" iyz="0.000001" izz="0.000866"/>
    </inertial>
    <visual>
      <origin rpy="0 0 0" xyz="0 0 0"/>
      <geometry>
        <mesh filename="package://humanoid_description/meshes/mit_humanoid/left_shoulder1.stl" scale="0.001 0.001 0.001"/>
      </geometry>
    </visual>
  </link>
  <joint name="left_shoulder_pitch_joint" type="fixed">
    <origin rpy="0 0.524 0" xyz="0.01911 0.17608 0.30392"/>
    <parent link="torso"/>
    <child link="left_shoulder"/>
    <axis xyz="0 1 0"/>
    <limit effort="34" lower="-6.28" upper="6.28" velocity="50"/>
    <dynamics damping="0.01" friction="0.2" rotor_inertia="0.01188"/>
  </joint>
  <link name="left_shoulder_2">
    <inertial>
      <origin rpy="0 0 0" xyz="0.000117 0.000122 -0.082758"/>
      <mass value="0.801249"/>
      <inertia ixx="0.001136" ixy="0.0" ixz="0.000016" iyy="0.001175" iyz="0.0" izz="0.001241"/>
    </inertial>
    <visual>
      <origin rpy="0 0 0" xyz="0 0 0"/>
      <geometry>
        <mesh filename="package://humanoid_description/meshes/mit_humanoid/left_shoulder2.stl" scale="0.001 0.001 0.001"/>
      </geometry>
    </visual>
  </link>
  <joint name="left_shoulder_abad_joint" type="fixed">
    <origin rpy="0 0 0" xyz="0 0.05760 0"/>
    <parent link="left_shoulder"/>
    <child link="left_shoulder_2"/>
    <axis xyz="1 0 0"/>
    <limit effort="34" lower="-6.28" upper="6.28" velocity="50"/>
    <dynamics damping="0.01" friction="0.2" rotor_inertia="0.01188"/>
  </joint>
  <link name="left_upper_arm">
    <inertial>
      <origin rpy="0 0 0" xyz="-0.000073 -0.016471 -0.063210"/>
      <mass value="0.905588"/>
      <inertia ixx="0.001353" ixy="0.0" ixz="0.0" iyy="0.001804" iyz="-0.000061" izz="0.000796"/>
    </inertial>
    <visual>
      <origin rpy="0 0 0" xyz="0 0 0"/>
      <geometry>
        <mesh filename="package://humanoid_description/meshes/mit_humanoid/left_shoulder3.stl" scale="0.001 0.001 0.001"/>
      </geometry>
    </visual>
    <collision>
      <origin rpy="0 0 0" xyz="0 -0.01 -0.035"/>
      <geometry>
        <cylinder length="0.15" radius="0.05"/>
      </geometry>
    </collision>
  </link>
  <joint name="left_shoulder_yaw_joint" type="fixed">
    <origin rpy="0.0 0 0" xyz="0 0 -0.10250"/>
    <parent link="left_shoulder_2"/>
    <child link="left_upper_arm"/>
    <axis xyz="0 0 -1"/>
    <limit effort="34" lower="-6.28" upper="6.28" velocity="50"/>
    <dynamics damping="0.01" friction="0.2" rotor_inertia="0.01188"/>
  </joint>
  <link name="left_lower_arm">
    <inertial>
      <origin rpy="0 0 0" xyz="-0.007103 -0.000073 -0.099203"/>
      <mass value="0.348390"/>
      <inertia ixx="0.003400" ixy="0.0" ixz="-0.000049" iyy="0.003453" iyz="0.0" izz="0.000078"/>
    </inertial>
    <visual>
      <origin rpy="0 0 0" xyz="0 0 0"/>
      <geometry>
        <mesh filename="package://humanoid_description/meshes/mit_humanoid/left_forearm.stl" scale="0.001 0.001 0.001"/>
      </geometry>
    </visual>
    <collision>
      <origin rpy="0 0 0" xyz="-0.01 0 -0.15"/>
      <geometry>
        <cylinder length="0.15" radius="0.025"/>
      </geometry>
    </collision>
  </link>
  <joint name="left_elbow_joint" type="fixed">
    <origin rpy="0 -1.57 0.0" xyz="0 0 -0.15750"/>
    <parent link="left_upper_arm"/>
    <child link="left_lower_arm"/>
    <axis xyz="0 1 0"/>
    <limit effort="55" lower="-6.28" upper="6.28" velocity="50"/>
    <dynamics damping="0.01" friction="0.2" rotor_inertia="0.0304"/>
  </joint>
  <link name="left_hand">
    <inertial>
      <origin rpy="0 0 0" xyz="0.0 -0.0 -0.27"/>
      <mass value="0.01"/>
      <inertia ixx="0.0" ixy="0.0" ixz="0.0" iyy="0.0" iyz="0.0" izz="0.0"/>
    </inertial>
    <collision>
      <origin rpy="1.57079 0 0" xyz="0.0 0.0 0."/>
      <geometry>
        <cylinder length="0.015" radius="0.025"/>
      </geometry>
    </collision>
  </link>
  <joint name="left_hand_joint" type="fixed">
    <origin rpy="0 0 0" xyz="0 0 -0.27"/>
    <parent link="left_lower_arm"/>
    <child link="left_hand"/>
  </joint>
  <link name="right_shoulder">
    <inertial>
      <origin rpy="0 0 0" xyz="0.009518 -0.053027 0.000060"/>
      <mass value="0.788506"/>
      <inertia ixx="0.001363" ixy="-0.000024" ixz="-0.000002" iyy="0.000759" iyz="-0.000001" izz="0.000866"/>
    </inertial>
    <visual>
      <origin rpy="0 0 0" xyz="0 0 0"/>
      <geometry>
        <mesh filename="package://humanoid_description/meshes/mit_humanoid/left_shoulder1.stl" scale="0.001 -0.001 0.001"/>
      </geometry>
    </visual>
  </link>
  <joint name="right_shoulder_pitch_joint" type="fixed">
    <origin rpy="0 0.524 0" xyz="0.01911 -0.17608 0.30392"/>
    <parent link="torso"/>
    <child link="right_shoulder"/>
    <axis xyz="0 1 0"/>
    <limit effort="34" lower="-6.28" upper="6.28" velocity="50"/>
    <dynamics damping="0.01" friction="0.2" rotor_inertia="0.01188"/>
  </joint>
  <link name="right_shoulder_2">
    <inertial>
      <origin rpy="0 0 0" xyz="0.000117 -0.000122 -0.082758"/>
      <mass value="0.801249"/>
      <inertia ixx="0.001136" ixy="0.0" ixz="0.000016" iyy="0.001175" iyz="0.0" izz="0.001241"/>
    </inertial>
    <visual>
      <origin rpy="0 0 0" xyz="0 0 0"/>
      <geometry>
        <mesh filename="package://humanoid_description/meshes/mit_humanoid/left_shoulder2.stl" scale="0.001 -0.001 0.001"/>
      </geometry>
    </visual>
  </link>
  <joint name="right_shoulder_abad_joint" type="fixed">
    <origin rpy="0 0 0" xyz="0 -0.05760 0"/>
    <parent link="right_shoulder"/>
    <child link="right_shoulder_2"/>
    <axis xyz="-1 0 0"/>
    <limit effort="34" lower="-6.28" upper="6.28" velocity="50"/>
    <dynamics damping="0.01" friction="0.2" rotor_inertia="0.01188"/>
  </joint>
  <link name="right_upper_arm">
    <inertial>
      <origin rpy="0 0 0" xyz="-0.000073 0.016471 -0.063210"/>
      <mass value="0.905588"/>
      <inertia ixx="0.001353" ixy="0.0" ixz="0.0" iyy="0.001804" iyz="0.000061" izz="0.000796"/>
    </inertial>
    <visual>
      <origin rpy="0 0 0" xyz="0 0 0"/>
      <geometry>
        <mesh filename="package://humanoid_description/meshes/mit_humanoid/left_shoulder3.stl" scale="0.001 -0.001 0.001"/>
      </geometry>
    </visual>
    <collision>
      <origin rpy="0 0 0" xyz="0 -0.01 -0.035"/>
      <geometry>
        <cylinder length="0.15" radius="0.05"/>
      </geometry>
    </collision>
  </link>
  <joint name="right_shoulder_yaw_joint" type="fixed">
    <origin rpy="0.0 0 0" xyz="0 0 -0.10250"/>
    <parent link="right_shoulder_2"/>
    <child link="right_upper_arm"/>
    <axis xyz="0 0 1"/>
    <limit effort="34" lower="-6.28" upper="6.28" velocity="50"/>
    <dynamics damping="0.01" friction="0.2" rotor_inertia="0.01188"/>
  </joint>
  <link name="right_lower_arm">
    <inertial>
      <origin rpy="0 0 0" xyz="-0.007103 -0.000073 -0.099203"/>
      <mass value="0.348390"/>
      <inertia ixx="0.003400" ixy="0.0" ixz="-0.000049" iyy="0.003453" iyz="0.0" izz="0.000078"/>
    </inertial>
    <visual>
      <origin rpy="0 0 0" xyz="0 0 0"/>
      <geometry>
        <mesh filename="package://humanoid_description/meshes/mit_humanoid/left_forearm.stl" scale="0.001 0.001 0.001"/>
      </geometry>
    </visual>
    <collision>
      <origin rpy="0 0 0" xyz="-0.01 0 -0.15"/>
      <geometry>
        <cylinder length="0.15" radius="0.025"/>
      </geometry>
    </collision>
  </link>
  <joint name="right_elbow_joint" type="fixed">
    <origin rpy="0 -1.57 0.0" xyz="0 0 -.15750"/>
    <parent link="right_upper_arm"/>
    <child link="right_lower_arm"/>
    <axis xyz="0 1 0"/>
    <limit effort="55" lower="-6.28" upper="6.28" velocity="50"/>
    <dynamics damping="0.01" friction="0.2" rotor_inertia="0.0304"/>
  </joint>
  <link name="right_hand">
    <inertial>
      <origin rpy="0 0 0" xyz="0.0 -0.0 -0.27"/>
      <mass value="0.01"/>
      <inertia ixx="0.0" ixy="0.0" ixz="0.0" iyy="0.0" iyz="0.0" izz="0.0"/>
    </inertial>
    <collision>
      <origin rpy="1.57079 0 0" xyz="0.0 0.0 0."/>
      <geometry>
        <cylinder length="0.015" radius="0.025"/>
      </geometry>
    </collision>
  </link>
  <joint name="right_hand_joint" type="fixed">
    <origin rpy="0 0 0" xyz="0 0 -0.27"/>
    <parent link="right_lower_arm"/>
    <child link="right_hand"/>
  </joint>
  <gazebo>
    <plugin filename="libgazebo_ros_control.so" name="gazebo_ros_control">
      <robotNamespace>mit_humanoid</robotNamespace>
      <robotSimType>gazebo_ros_control/DefaultRobotHWSim</robotSimType>
    </plugin>
  </gazebo>
  <gazebo>
    <plugin filename="libgazebo_ros_p3d.so" name="p3d">
      <always_on>true</always_on>
      <update_rate>2000</update_rate>
      <bodyName>torso_com</bodyName>
      <topicName>mit_humanoid/torso_com_odom</topicName>
      <frameName>world</frameName>
      <xyzOffset>0 0 0</xyzOffset>
      <rpyOffset>0 0 0</rpyOffset>
    </plugin>
  </gazebo>
  <gazebo reference="torso_com">
    <gravity>true</gravity>
    <sensor name="imu_sensor" type="imu">
      <always_on>true</always_on>
      <update_rate>2000</update_rate>
      <visualize>true</visualize>
      <topic>__default_topic__</topic>
      <plugin filename="libgazebo_ros_imu_sensor.so" name="imu_plugin">
        <topicName>mit_humanoid/torso_imu</topicName>
        <bodyName>torso_com</bodyName>
        <updateRateHZ>2000</updateRateHZ>
        <gaussianNoise>0.0</gaussianNoise>
        <frameName>torso_com</frameName>
        <xyzOffset>0 0 0</xyzOffset>
        <rpyOffset>0 0 0</rpyOffset>
      </plugin>
      <pose>0 0 0 0 0 0</pose>
    </sensor>
  </gazebo>
  <link name="base">
    <visual>
      <origin rpy="0 0 0" xyz="0 0 0"/>
      <geometry>
        <box size="0.001 0.001 0.001"/>
      </geometry>
    </visual>
  </link>
  <link name="torso">
    <inertial>
      <origin rpy="0 0 0" xyz="0.009598 0.000935 0.151714"/>
      <mass value="7.954054"/>
      <inertia ixx="0.168459" ixy="0.0" ixz="0.006493" iyy="0.101358" iyz="0.0" izz="0.091754"/>
    </inertial>
    <visual>
      <origin rpy="0 0 0" xyz="0 0 0"/>
      <geometry>
        <mesh filename="package://humanoid_description/meshes/mit_humanoid/torso.stl" scale="0.001 0.001 0.001"/>
      </geometry>
    </visual>
    <collision>
      <origin rpy="0 0 0" xyz="0.023 0. 0.08"/>
      <geometry>
        <box size="0.15 0.3 0.35"/>
      </geometry>
    </collision>
  </link>
  <joint name="floating_base" type="fixed">
    <origin rpy="0 0 0" xyz="0 0 0"/>
    <parent link="base"/>
    <child link="torso"/>
  </joint>
  <link name="torso_com">
    <visual>
      <origin rpy="0 0 0" xyz="0 0 0"/>
      <geometry>
        <sphere radius="0.001"/>
      </geometry>
    </visual>
  </link>
  <joint name="torso_com_joint" type="fixed">
    <origin rpy="0 0 0" xyz="-0.003261 0.0 0.172278"/>
    <parent link="torso"/>
    <child link="torso_com"/>
  </joint>
  <transmission name="left_hip_yaw_trans">
    <type>transmission_interface/SimpleTransmission</type>
    <joint name="left_hip_yaw_joint">
      <hardwareInterface>hardware_interface/EffortJointInterface</hardwareInterface>
    </joint>
    <actuator name="left_hip_yaw_actuator">
      <hardwareInterface>hardware_interface/EffortJointInterface</hardwareInterface>
      <mechanicalReduction>1</mechanicalReduction>
    </actuator>
  </transmission>
  <transmission name="left_hip_abad_trans">
    <type>transmission_interface/SimpleTransmission</type>
    <joint name="left_hip_abad_joint">
      <hardwareInterface>hardware_interface/EffortJointInterface</hardwareInterface>
    </joint>
    <actuator name="left_hip_abad_actuator">
      <hardwareInterface>hardware_interface/EffortJointInterface</hardwareInterface>
      <mechanicalReduction>1</mechanicalReduction>
    </actuator>
  </transmission>
  <transmission name="left_hip_pitch_trans">
    <type>transmission_interface/SimpleTransmission</type>
    <joint name="left_hip_pitch_joint">
      <hardwareInterface>hardware_interface/EffortJointInterface</hardwareInterface>
    </joint>
    <actuator name="left_hip_pitch_actuator">
      <hardwareInterface>hardware_interface/EffortJointInterface</hardwareInterface>
      <mechanicalReduction>1</mechanicalReduction>
    </actuator>
  </transmission>
  <transmission name="left_knee_trans">
    <type>transmission_interface/SimpleTransmission</type>
    <joint name="left_knee_joint">
      <hardwareInterface>hardware_interface/EffortJointInterface</hardwareInterface>
    </joint>
    <actuator name="left_knee_actuator">
      <hardwareInterface>hardware_interface/EffortJointInterface</hardwareInterface>
      <mechanicalReduction>1</mechanicalReduction>
    </actuator>
  </transmission>
  <transmission name="left_ankle_trans">
    <type>transmission_interface/SimpleTransmission</type>
    <joint name="left_ankle_joint">
      <hardwareInterface>hardware_interface/EffortJointInterface</hardwareInterface>
    </joint>
    <actuator name="left_ankle_actuator">
      <hardwareInterface>hardware_interface/EffortJointInterface</hardwareInterface>
      <mechanicalReduction>1</mechanicalReduction>
    </actuator>
  </transmission>
  <transmission name="right_hip_yaw_trans">
    <type>transmission_interface/SimpleTransmission</type>
    <joint name="right_hip_yaw_joint">
      <hardwareInterface>hardware_interface/EffortJointInterface</hardwareInterface>
    </joint>
    <actuator name="right_hip_yaw_actuator">
      <hardwareInterface>hardware_interface/EffortJointInterface</hardwareInterface>
      <mechanicalReduction>1</mechanicalReduction>
    </actuator>
  </transmission>
  <transmission name="right_hip_abad_trans">
    <type>transmission_interface/SimpleTransmission</type>
    <joint name="right_hip_abad_joint">
      <hardwareInterface>hardware_interface/EffortJointInterface</hardwareInterface>
    </joint>
    <actuator name="right_hip_abad_actuator">
      <hardwareInterface>hardware_interface/EffortJointInterface</hardwareInterface>
      <mechanicalReduction>1</mechanicalReduction>
    </actuator>
  </transmission>
  <transmission name="right_hip_pitch_trans">
    <type>transmission_interface/SimpleTransmission</type>
    <joint name="right_hip_pitch_joint">
      <hardwareInterface>hardware_interface/EffortJointInterface</hardwareInterface>
    </joint>
    <actuator name="right_hip_pitch_actuator">
      <hardwareInterface>hardware_interface/EffortJointInterface</hardwareInterface>
      <mechanicalReduction>1</mechanicalReduction>
    </actuator>
  </transmission>
  <transmission name="right_knee_trans">
    <type>transmission_interface/SimpleTransmission</type>
    <joint name="right_knee_joint">
      <hardwareInterface>hardware_interface/EffortJointInterface</hardwareInterface>
    </joint>
    <actuator name="right_knee_actuator">
      <hardwareInterface>hardware_interface/EffortJointInterface</hardwareInterface>
      <mechanicalReduction>1</mechanicalReduction>
    </actuator>
  </transmission>
  <transmission name="right_ankle_trans">
    <type>transmission_interface/SimpleTransmission</type>
    <joint name="right_ankle_joint">
      <hardwareInterface>hardware_interface/EffortJointInterface</hardwareInterface>
    </joint>
    <actuator name="right_ankle_actuator">
      <hardwareInterface>hardware_interface/EffortJointInterface</hardwareInterface>
      <mechanicalReduction>1</mechanicalReduction>
    </actuator>
  </transmission>
</robot>

